Workbook
Name for_fulltext_screening: 'Full Text Screening'!$A$1:$E$123
Name SLR_Include_In_Review: review_zotero_export!$A$1:$CH$43

Sheet Title Abstract Screening
A1: Screening | B1: Notes | C1: Key | D1: Item Type | E1: Publication Year | F1: Author | G1: Title | H1: Publication Title | I1: ISBN | J1: ISSN | K1: DOI | L1: Url | M1: Abstract Note | N1: Date | O1: Date Added | P1: Date Modified | Q1: Access Date | R1: Pages | S1: Num Pages | T1: Issue | U1: Volume | V1: Number Of Volumes | W1: Journal Abbreviation | X1: Short Title | Y1: Series | Z1: Series Number | AA1: Series Text | AB1: Series Title | AC1: Publisher | AD1: Place | AE1: Language | AF1: Rights | AG1: Type | AH1: Archive | AI1: Archive Location | AJ1: Library Catalog | AK1: Call Number | AL1: Extra | AM1: Notes | AN1: File Attachments | AO1: Link Attachments | AP1: Manual Tags | AQ1: Automatic Tags | AR1: Editor | AS1: Series Editor | AT1: Translator | AU1: Contributor | AV1: Attorney Agent | AW1: Book Author | AX1: Cast Member | AY1: Commenter | AZ1: Composer | BA1: Cosponsor | BB1: Counsel | BC1: Interviewer | BD1: Producer | BE1: Recipient | BF1: Reviewed Author | BG1: Scriptwriter | BH1: Words By | BI1: Guest | BJ1: Number | BK1: Edition | BL1: Running Time | BM1: Scale | BN1: Medium | BO1: Artwork Size | BP1: Filing Date | BQ1: Application Number | BR1: Assignee | BS1: Issuing Authority | BT1: Country | BU1: Meeting Name | BV1: Conference Name | BW1: Court | BX1: References | BY1: Reporter | BZ1: Legal Status | CA1: Priority Numbers | CB1: Programming Language | CC1: Version | CD1: System | CE1: Code | CF1: Code Number | CG1: Section | CH1: Session | CI1: Committee | CJ1: History | CK1: Legislative Body
A2: exclude | B2: only questionnaires | C2: 2SJXTDKX | D2: conferencePaper | E2: 2019 | F2: Abdi Oskouie, Mina; Boulanger, Pierre | G2: Using Proxy Haptic for a Pointing Task in the Virtual World: A Usability Study | H2: Augmented Reality, Virtual Reality, and Computer Graphics: 6th International Conference, AVR 2019, Santa Maria al Bagno, Italy, June 24–27, 2019, Proceedings, Part I | I2: 978-3-030-25964-8 | K2: 10.1007/978-3-030-25965-5_21 | L2: https://doi.org/10.1007/978-3-030-25965-5_21 | M2: Virtual Reality (VR) applications are getting progressively more popular in many disciplines. This is mainly due to (1) technological advancement in rendering images and sounds, and (2) immersive experience of VR which intensifies users’ engagement leading to improved joy, sense of presence and success. Although VR creates a realistic experience by simulating visual and auditory sense, it ignores other human senses. The absence of haptic feedback in Virtual Environments (VE) can impair users’ engagement. Our objective is to provide haptic feedback in VE using the most affordable method, proxy haptics. Proxies are physical objects which are co-registered with virtual objects in a way that by touching the proxies, users see their virtual hand touching the virtual objects. So, the haptic feedback will be applied to users’ hands by touching the proxies. The important question which arises here is: what are the influences of providing haptic feedback on users’ performance and usability? In this work, we have designed an experiment in Virtual Reality to answer this question. In the virtual environment, we presented a keyboard with touchable keys and asked our participants to type three words using the keyboard. They repeated the experiment twice: once they used their own hands and pressed the keys and once they used VR controllers for typing. Our results show that participants can type words with fewer errors when they are using their own hands while they found VR controllers easier to use. | N2: 2019 | O2: 45783.306 | P2: 45783.306 | R2: 292–299 | AC2: Springer-Verlag | AD2: Berlin, Heidelberg | AL2: event-place: Santa Maria al Bagno, Italy | AP2: Virtual Reality; Usability test; Passive haptic; Sense of touch
A3: exclude | B3: no AR/VR | C3: IRY3WI6P | D3: conferencePaper | E3: 2012 | F3: Abdul Rahim, Elin; Duenser, Andreas; Billinghurst, Mark; Herritsch, Alfred; Unsworth, Keith; Mckinnon, Alan; Gostomski, Peter | G3: A desktop virtual reality application for chemical and process engineering education | H3: Proceedings of the 24th Australian Computer-Human Interaction Conference | I3: 978-1-4503-1438-1 | K3: 10.1145/2414536.2414537 | L3: https://doi.org/10.1145/2414536.2414537 | M3: A desktop Virtual Reality (VR) application of a skim milk powder process has been developed. The goal was to use this application as a learning resource to expose students to processing plant environments, which are becoming increasingly difficult to visit due to availability and safety reasons. The VR application comprises 360° panorama images of the milk powder process plant, process flow diagrams (PFD), piping and instrumentation diagrams (P&amp;ID), 3D drawings and additional materials such as supplemental text, videos and animations. This paper describes the VR application as well as an evaluation of the application. The results of this study show that the application was easy to use and the users were satisfied with it. The design recommendations for the development of similar VR learning applications are also discussed in this paper. | N3: 2012 | O3: 45783.306 | P3: 45783.306 | R3: 1–8 | Y3: OzCHI '12 | AC3: Association for Computing Machinery | AD3: New York, NY, USA | AL3: event-place: Melbourne, Australia | AP3: usability; virtual reality; evaluation; educational software; engineering
A4: exclude | B4: only questionnaires | C4: CFXDR833 | D4: conferencePaper | E4: 2012 | F4: Abu Shanab, Shatha; Odeh, Salaheddin; Hodrob, Rami; Anabtawi, Mahasen | G4: Augmented reality internet labs versus hands-on and virtual labs: A comparative study | H4: Proceedings of 2012 International Conference on Interactive Mobile and Computer Aided Learning (IMCL) | I4: 978-1-4673-4925-3 978-1-4673-4924-6 978-1-4673-4923-9 | K4: 10.1109/IMCL.2012.6396444 | L4: http://ieeexplore.ieee.org/document/6396444/ | N4: 2012-11 | O4: 45783.312 | P4: 45783.312 | Q4: 45783.312 | R4: 17-21 | X4: Augmented reality internet labs versus hands-on and virtual labs | AC4: IEEE | AD4: Amman, Jordan | AJ4: DOI.org (Crossref) | BV4: 2012 International Conference on Interactive Mobile and Computer Aided Learning (IMCL)
A5: for-fulltext | B5: physiological factors | C5: WBUZ3SQ5 | D5: conferencePaper | E5: 2023 | F5: Döllinger, Nina; Beck, Matthias; Wolf, Erik; Mal, David; Botsch, Mario; Latoschik, Marc Erich; Wienrich, Carolin | G5: “If It’s Not Me It Doesn’t Make a Difference” - The Impact of Avatar Personalization on user Experience and Body Awareness in Virtual Reality | H5: 2023 IEEE International Symposium on Mixed and Augmented Reality (ISMAR) | I5: 979-8-3503-2838-7 | K5: 10.1109/ISMAR59233.2023.00063 | L5: https://ieeexplore.ieee.org/document/10316447/ | N5: 45215 | O5: 45783.312 | P5: 45783.312 | Q5: 45783.312 | R5: 483-492 | AC5: IEEE | AD5: Sydney, Australia | AJ5: DOI.org (Crossref) | AN5: /Users/dennis/Zotero/storage/EVB7ZX4B/Döllinger et al. - 2023 - “If It’s Not Me It Doesn’t Make a Difference” - The Impact of Avatar Personalization on user Experie.pdf | BV5: 2023 IEEE International Symposium on Mixed and Augmented Reality (ISMAR)
A6: exclude | B6: irrelevant | C6: Q6JQP3VK | D6: conferencePaper | E6: 2024 | F6: Adriana, M.; Daniel, C.; Cosmin, M. | G6: MediQApp: Advanced Integration of Risk Digitization in E-Health and E-Learning Domains | H6: IFMBE Proc. | I6: 16800737 (ISSN); 978-303162501-5 (ISBN) | K6: 10.1007/978-3-031-62502-2_42 | L6: https://www.scopus.com/inward/record.uri?eid=2-s2.0-85210094429&doi=10.1007%2f978-3-031-62502-2_42&partnerID=40&md5=4dcf2e943a6778fb103f9eb3e7756669 | M6: This scientific research explores the integration of advanced digital automation in healthcare, focusing on its application in mitigating clinical risks across various surgical disciplines. The latest MediQApp (version 5.0) represents a significant advancement in this field, effectively combining E-Health with ELearning. This version has undergone comprehensive evaluations through document analysis, quality management audits, clinical audits, direct observation of hospital activities, process simulations, testing, and extensive user feedback. These evaluations have underscored its efficacy in streamlining risk management and improving operational efficiency within healthcare settings. MediQApp has particularly excelled in user experience, offering an intuitive interface and easy navigation, significantly enhancing user satisfaction among healthcare professionals. The application also shows promise in expanding its capabilities to include predictive analytics, VR/AR integration for training and patient care, and blockchain technology for enhanced data security, positioning it as a pivotal tool in the ongoing digital transformation of the healthcare industry. © The Author(s), under exclusive license to Springer Nature Switzerland AG 2024. | N6: 2024 | O6: 45783.3 | P6: 45783.3 | R6: 359-366 | U6: 109 | AC6: Springer Science and Business Media Deutschland GmbH | AE6: English | AH6: Scopus | AL6: Journal Abbreviation: IFMBE Proc. | AP6: Risk management; E - learning; Clinical research; Electronic health record; Analysis; Analyze; Clinical risks; Digital automation; Digitisation; E health; E-Health; E-Learning; eHealth; ITS applications; Medical Application; Mediqapp; MediQApp; Process Simulation; Process simulations; Scientific researches | AR6: Costin H.-N.; Petroiu G.G.; Magjarevic R. | BV6: IFMBE Proceedings
A7: for-fulltext | B7: usability evaluation unclear, read fulltext | C7: IDTU5H7Q | D7: conferencePaper | E7: 2010 | F7: Nakamura, Ricardo; Lago, Lucas L. M.; Carneiro, Alexandre B.; Cunha, Anderson J. C.; Ortega, Fábio J. M.; Bernardes, João L.; Tori, Romero | G7: 3PI experiment: immersion in third-person view | H7: Proceedings of the 5th ACM SIGGRAPH Symposium on Video Games | I7: 978-1-4503-0097-1 | K7: 10.1145/1836135.1836142 | L7: https://doi.org/10.1145/1836135.1836142 | M7: In this paper, we present the results of the "3PI Experiment" project. The objective of this project is to propose and evaluate an immersive interface based on a third-person view from a video camera, that can be used in augmented reality games. Since this type of interface has not been explored in games, a prototype involving interaction through navigation was developed and employed to assess the impact of the proposed interface on gameplay experience. Different user interface evaluation methods such as cognitive walkthroughs, automatic data collection and questionnaires were combined. It was possible to determine that the proposed interface caused no significant discomfort and had a short learning time, making it suitable for use in games. | N7: 2010 | O7: 45783.306 | P7: 45783.342 | R7: 43–48 | Y7: Sandbox '10 | AC7: Association for Computing Machinery | AD7: New York, NY, USA | AL7: event-place: Los Angeles, California | AP7: Virtual reality; augmented reality; Augmented reality; Immersive; User interfaces; User experience; Interactive computer graphics; Gameplay; Augmented-reality games; Automatic data collection; Game user experience; Interface evaluation; Learning time; User interface evaluation; Video cameras; Walkthroughs; game user experience; user interface evaluation
A8: exclude | B8: only questionnaires | C8: ZF82HSQR | D8: journalArticle | E8: 2024 | F8: Afyouni, Imad; Lataifeh, Mohammed; Afrah, Zulaiha; Ahmed, Naveed | G8: Usability Evaluation of Handheld and Wearable AR devices: Exploring Collaboration and the Role of Physical Props | H8: Procedia Comput. Sci. | J8: 1877-0509 | K8: 10.1016/j.procs.2023.12.156 | L8: https://doi.org/10.1016/j.procs.2023.12.156 | N8: 2024-01 | O8: 45783.306 | P8: 45783.306 | R8: 48–55 | T8: C | U8: 231 | AL8: Place: NLD Publisher: Elsevier Science Publishers B. V. | AP8: Augmented Reality; Collaboration; Physical Props; User Interaction
A9: exclude | B9: only questionnaires | C9: MKLZC2Z8 | D9: conferencePaper | E9: 2024 | F9: Aguilar, Samantha D.; Qian, Chengyuan; Monjoree, Uttamasha; Burte, Heather; Liew, Jeffrey; Queck, Francis; Yasskin, Philip; Song, Dezhen; Yan, Wei | G9: AR-Classroom Usability: Implications for UX Research on AR-Enabled Educational Technologies for 3D Matrix Algebra Learning | H9: 2024 IEEE Frontiers in Education Conference (FIE) | I9: 979-8-3503-5150-7 | K9: 10.1109/FIE61694.2024.10892900 | L9: https://ieeexplore.ieee.org/document/10892900/ | N9: 45578 | O9: 45783.313 | P9: 45783.313 | Q9: 45783.313 | R9: 45870 | X9: AR-Classroom Usability | AC9: IEEE | AD9: Washington, DC, USA | AF9: https://doi.org/10.15223/policy-029 | AJ9: DOI.org (Crossref) | BV9: 2024 IEEE Frontiers in Education Conference (FIE)
A10: exclude | B10: only questionnaires | C10: RBIZ8XGT | D10: conferencePaper | E10: 2023 | F10: Ahmed Alnagrat, Ahmed Jamah; Ismail Alkhallas, Muhannad; Imhmed Mohamed, Abdalslam S; Che Ismail, Rizalafande; Syed Idrus, Syed Zulkarnain; Salem Saed, Halifah | G10: Virtual Reality Semiconductor Laboratory: Usability Testing to Improve User Experience (UX) in Virtual Environments | H10: 2023 IEEE 3rd International Maghreb Meeting of the Conference on Sciences and Techniques of Automatic Control and Computer Engineering (MI-STA) | I10: 979-8-3503-1989-7 | K10: 10.1109/MI-STA57575.2023.10169788 | L10: https://ieeexplore.ieee.org/document/10169788/ | N10: 45067 | O10: 45783.311 | P10: 45783.311 | Q10: 45783.311 | R10: 469-473 | X10: Virtual Reality Semiconductor Laboratory | AC10: IEEE | AD10: Benghazi, Libya | AF10: https://doi.org/10.15223/policy-029 | AJ10: DOI.org (Crossref) | BV10: 2023 IEEE 3rd International Maghreb Meeting of the Conference on Sciences and Techniques of Automatic Control and Computer Engineering (MI-STA)
A11: exclude | B11: irrelevant | C11: P38B4ND4 | D11: journalArticle | E11: 2016 | F11: Aita, K.S.U.; Monte, S.J.H.; Silva, A.S.; Marroquim, M.S.C.; Coelho, A.G.B.; Sousa, L.C.D.M. | G11: Web-based ecosystem software for virtual crossmatching in transplant programs | H11: Computers in Biology and Medicine | J11: 00104825 (ISSN) | K11: 10.1016/j.compbiomed.2016.05.010 | L11: https://www.scopus.com/inward/record.uri?eid=2-s2.0-84969752647&doi=10.1016%2fj.compbiomed.2016.05.010&partnerID=40&md5=eecbc739a074507268672bd503ab0b5f | M11: Background: The compatibilities between donors and recipients are extremely important for evaluating the immunological risks of transplants. One challenge faced by data analysis tools is the transformation of complex data into simple, intuitive, and important information that can be used to resolve contemporary problems. To address this challenge, we developed the EpViX software to perform epitope reactivity analyses and automated epitope virtual crossmatching. EpViX is a facilitator of medical decision-making regarding the identification of the best donor for a high-immunologic risk recipient. The objective of this work is to describe the computational architecture of the EpViX ecosystem (http://www.epvix.com.br). Materials and methods: EpViX is a freeware on the web that was developed in the Ruby language. EpViX can be accessed from different platforms, e.g., PCs, tablets, and smartphones. It consists of an ecosystem of tools that are capable of integrating all of the stakeholders who are involved in a transplant process with a deceased donor. Results: We successfully developed a program that allows people to work collaboratively and effectively during the donation process by accurately predicting negative crossmatches, saving time and other resources. Conclusions: EpViX represents a significant breakthrough for the organ transplant process and may meet the current needs of transplant programs because it increases the chances of the allocation of low-immunologic risk donors to highly sensitized recipients and assures greater equity among the recipients on a waiting list. EpViX was duly verified and tested in terms of data security. Moreover, usability tests demonstrated that EpViX is an intuitive and easy-to-use tool. © 2016 Elsevier Ltd. | N11: 2016 | O11: 45783.3 | P11: 45783.3 | R11: 30-37 | U11: 75 | W11: Comput. Biol. Med. | AE11: English | AH11: Scopus | AL11: Publisher: Elsevier Ltd | AP11: virtual reality; Humans; Article; automation; human; procedures; time; Virtual addresses; Behavioral research; Usability tests; Decision making; Internet; priority journal; mobile application; smartphone; Ecosystems; Websites; cadaver donor; Computational architecture; computer language; computer program; Data analysis tool; Decision-making; donor; donor selection; Ecology; ecosystem; epitope; Epitope reactivity analyses; Epitopes; histocompatibility test; Histocompatibility Testing; HLA epitopes; medical decision making; Medical decision making; Metadata; Mobile Applications; organ transplantation; Organ Transplantation; Organ transplants; Programming Languages; Reactivity analysis; recipient; transplantation; Virtual crossmatch; Web-based software; Web-based softwares; World Wide Web
A12: exclude | B12: only questionnaires + interviews | C12: 5LF367YK | D12: conferencePaper | E12: 2022 | F12: Aldea, Anna; Tinga, Angelica M.; Van Zeumeren, Ilse M.; Van Nes, Nicole; Aschenbrenner, Doris | G12: Virtual Reality Tool for Human-Machine Interface Evaluation and Development (VRHEAD) | H12: 2022 IEEE Intelligent Vehicles Symposium (IV) | I12: 978-1-6654-8821-1 | K12: 10.1109/IV51971.2022.9827375 | L12: https://ieeexplore.ieee.org/document/9827375/ | N12: 44717 | O12: 45783.314 | P12: 45784.289 | Q12: 45783.314 | R12: 151-158 | AC12: IEEE | AD12: Aachen, Germany | AF12: https://doi.org/10.15223/policy-029 | AJ12: DOI.org (Crossref) | AN12: /Users/dennis/Zotero/storage/4AIENRKJ/Aldea et al. - 2022 - Virtual Reality Tool for Human-Machine Interface Evaluation and Development (VRHEAD).pdf | AP12: automated driving; Automated driving; Automation; design evaluation; Design evaluation; design for experiments; Design for experiments; Design-process; HMI; Human Centered Design; Human machine interaction; Human Machine Interface; Human-centred designs; human-machine interaction; Iterative design; iterative design process; Iterative design process; Man machine systems; mode awareness; Mode awareness; rapid prototyping; Rapid-prototyping; Vehicles; Virtual prototyping; virtual reality; Virtual reality | BV12: 2022 IEEE Intelligent Vehicles Symposium (IV)
A13: exclude | B13: literature review | C13: LRNIUZQZ | D13: conferencePaper | E13: 2024 | F13: Aldhous, Joanna; Sobolewska, Emilia; Webster, Gemma | G13: Evaluating Human Experiences of Touching Virtual Reality: A State of The Art Review | H13: 2024 IEEE International Conference on Metrology for eXtended Reality, Artificial Intelligence and Neural Engineering (MetroXRAINE) | I13: 979-8-3503-7800-9 | K13: 10.1109/MetroXRAINE62247.2024.10797081 | L13: https://ieeexplore.ieee.org/document/10797081/ | N13: 45586 | O13: 45783.313 | P13: 45783.313 | Q13: 45783.313 | R13: 243-248 | X13: Evaluating Human Experiences of Touching Virtual Reality | AC13: IEEE | AD13: St Albans, United Kingdom | AF13: https://doi.org/10.15223/policy-029 | AJ13: DOI.org (Crossref) | BV13: 2024 IEEE International Conference on Metrology for eXtended Reality, Artificial Intelligence and Neural Engineering (MetroXRAINE)
A14: exclude | B14: only questionnaires + interviews | C14: 5NVYZS9D | D14: conferencePaper | E14: 2021 | F14: Alenljung, Zackarias; Lindblom, Jessica | G14: User Experience in Augmented Reality: A Holistic Evaluation of a Prototype for Assembly Instructions | H14: Design, User Experience, and Usability: Design for Contemporary Technological Environments: 10th International Conference, DUXU 2021, Held as Part of the 23rd HCI International Conference, HCII 2021, Virtual Event, July 24–29, 2021, Proceedings, Part III | I14: 978-3-030-78226-9 | K14: 10.1007/978-3-030-78227-6_11 | L14: https://doi.org/10.1007/978-3-030-78227-6_11 | M14: Industries are under development with new upcoming tools that will further streamline the work of operators, not least in assembly. Assembly instructions are usually visualized by traditional paper or data bases. A new way of showing instruction is provided by augmented reality (AR). The focus of this paper is the user experience (UX) of AR based instructions for assembly. In order to study the UX in AR an evaluation matrix and an AR prototype has been developed and evaluated in a UX test, where data regarding both hedonic and pragmatic qualities was collected. The UX test yielded a result of three out of nine sub-goals completed while six did not. There was a general low degree of cognitive load while assembling but not low enough. However, there are promising results for AR based instructions, though the technology still needs improvement and more testing is also necessary. The assembly scenario for this study was somewhat simple and could be one reason why this study generated ambiguous results. | N14: 2021 | O14: 45783.293 | P14: 45784.355 | R14: 139–157 | U14: 12781 | AC14: Springer-Verlag | AD14: Berlin, Heidelberg | AP14: Assembly instructions; Augmented reality; Evaluation; User experience
A15: exclude | B15: irrelevant | C15: XMKNEBVW | D15: conferencePaper | E15: 2019 | F15: Ali, G.; Le, H.-Q.; Kim, J.; Hwang, S.-W.; Hwang, J.-I. | G15: Design of seamless multi-modal interaction framework for intelligent virtual agents in wearable mixed reality environment | H15: ACM Int. Conf. Proc. Ser. | I15: 978-145037159-9 (ISBN) | K15: 10.1145/3328756.3328758 | L15: https://www.scopus.com/inward/record.uri?eid=2-s2.0-85069173185&doi=10.1145%2f3328756.3328758&partnerID=40&md5=29caf4599720e0058100ba9c42524850 | M15: In this paper, we present the design of a multimodal interaction framework for intelligent virtual agents in wearable mixed reality environments, especially for interactive applications at museums, botanical gardens, and similar places. These places need engaging and no-repetitive digital content delivery to maximize user involvement. An intelligent virtual agent is a promising mode for both purposes. Premises of framework is wearable mixed reality provided by MR devices supporting spatial mapping. We envisioned a seamless interaction framework by integrating potential features of spatial mapping, virtual character animations, speech recognition, gazing, domain-specific chatbot and object recognition to enhance virtual experiences and communication between users and virtual agents. By applying a modular approach and deploying computationally intensive modules on cloud-platform, we achieved a seamless virtual experience in a device with limited resources. Human-like gaze and speech interaction with a virtual agent made it more interactive. Automated mapping of body animations with the content of a speech made it more engaging. In our tests, the virtual agents responded within 2-4 seconds after the user query. The strength of the framework is flexibility and adaptability. It can be adapted to any wearable MR device supporting spatial mapping. © 2019 Association for Computing Machinery. | N15: 2019 | O15: 45783.3 | P15: 45783.3 | R15: 47-52 | AC15: Association for Computing Machinery | AE15: English | AH15: Scopus | AL15: Journal Abbreviation: ACM Int. Conf. Proc. Ser. | AP15: Animation; Mixed reality; User experience; Mixed-reality environment; Speech recognition; Mapping; Wearable technology; Arts computing; Automated mapping; Botanical gardens; Intelligent virtual agents; Interaction framework; Interactive applications; Multi-Modal Interactions; Object recognition; Potential features; Speech communication; Speech interaction | BV15: ACM International Conference Proceeding Series
A16: exclude | B16: only questionnaires | C16: RPZC3DMS | D16: conferencePaper | E16: 2022 | F16: Allgaier, Mareen; Chheang, Vuthea; Saalfeld, Patrick; Apilla, Vikram; Huber, Tobias; Huettl, Florentine; Neyazi, Belal; Sandalcioglu, I. Erol; Hansen, Christian; Preim, Bernhard; Saalfeld, Sylvia | G16: A Comparison of Input Devices for Precise Interaction Tasks in VR-based Surgical Planning and Training | H16: 2022 IEEE Conference on Virtual Reality and 3D User Interfaces Abstracts and Workshops (VRW) | I16: 978-1-6654-8402-2 | K16: 10.1109/VRW55335.2022.00188 | L16: https://ieeexplore.ieee.org/document/9757571/ | N16: 2022-03 | O16: 45783.312 | P16: 45783.312 | Q16: 45783.312 | R16: 674-675 | AC16: IEEE | AD16: Christchurch, New Zealand | AF16: https://doi.org/10.15223/policy-029 | AJ16: DOI.org (Crossref) | BV16: 2022 IEEE Conference on Virtual Reality and 3D User Interfaces Abstracts and Workshops (VRW)
A17: exclude | B17: irrelevant | C17: UI3BU2NZ | D17: journalArticle | E17: 2017 | F17: Alshammari, N.; Alshammari, T.; Sedky, M.; Champion, J.; Bauer, C. | G17: OpenSHS: Open smart home simulator | H17: Sensors (Switzerland) | J17: 14248220 (ISSN) | K17: 10.3390/s17051003 | L17: https://www.scopus.com/inward/record.uri?eid=2-s2.0-85018381371&doi=10.3390%2fs17051003&partnerID=40&md5=864fbd1d76962619913c868c9cfa6f19 | M17: This paper develops a new hybrid, open-source, cross-platform 3D smart home simulator, OpenSHS, for dataset generation. OpenSHS offers an opportunity for researchers in the field of the Internet of Things (IoT) and machine learning to test and evaluate their models. Following a hybrid approach, OpenSHS combines advantages from both interactive and model-based approaches. This approach reduces the time and efforts required to generate simulated smart home datasets. We have designed a replication algorithm for extending and expanding a dataset. A small sample dataset produced, by OpenSHS, can be extended without affecting the logical order of the events. The replication provides a solution for generating large representative smart home datasets. We have built an extensible library of smart devices that facilitates the simulation of current and future smart home environments. Our tool divides the dataset generation process into three distinct phases: first design: the researcher designs the initial virtual environment by building the home, importing smart devices and creating contexts; second, simulation: the participant simulates his/her context-specific events; and third, aggregation: the researcher applies the replication algorithm to generate the final dataset. We conducted a study to assess the ease of use of our tool on the System Usability Scale (SUS). © 2017 by the authors. Licensee MDPI, Basel, Switzerland. | N17: 2017 | O17: 45783.3 | P17: 45783.3 | T17: 5 | U17: 17 | W17: Sensors | AE17: English | AH17: Scopus | AL17: Publisher: MDPI AG | AP17: Automation; Virtual reality; Visualization; Learning systems; Smart home; Smart homes; Artificial intelligence; Simulation; Intelligent buildings; Internet of things; Machine learning; Extensible library; Internet of thing (IOT); Model based approach; Replication algorithm; Smart home simulators; System Usability Scale (SUS); Visualisation
A18: exclude | B18: only questionnaires | C18: K7NG6FQP | D18: journalArticle | E18: 2024 | F18: Álvarez, Ibis M.; Manero, Borja; Romero-Hernández, Alejandro; Cárdenas, Miriela; Masó, Isabel | G18: Virtual reality platform for teacher training on classroom climate management: evaluating user acceptance | H18: Virtual Real. | J18: 1359-4338 | K18: 10.1007/s10055-024-00973-6 | L18: https://doi.org/10.1007/s10055-024-00973-6 | M18: Enhancing the educational experience through Immersive Virtual Reality (IVR) is a promising avenue, elevating the authenticity and responsiveness of simulations. Particularly in educational settings, IVR holds the potential to augment accessibility and engagement in learning. However, one pivotal aspect lies in assessing the learners' acceptance of such environments to ensure optimal and effective utilization of these technologies. This paper delves into the Didascalia Virtual-ClassRoom usability testing —an immersive IVR environment tailored for pre-service secondary school teachers. The platform transports users into a simulated classroom, where they are invited to play the role of a teacher. During the simulation, three scenarios are recreated, reproducing disruptive behaviours commonly faced in real classrooms. 84 participants (28 teachers and 56 pre-service teachers) engaged in decision-making to manage the classroom climate influenced by the simulated situations. To collect data, we used a questionnaire based on the Technology Acceptance Model (TAM) to assess and gauge users' inclinations and attitudes towards embracing the technology in question. To gain deeper insights into the user experience, participants were further invited to participate in semi-structured interviews, offering reflections and suggestions for potential enhancements. The evaluation process encompassed the perceived usefulness of the Didascalia Virtual-ClassRoom, shedding light on factors that could either facilitate or impede the adoption of this platform to enhance classroom management competence. The participants' perspectives serve as a valuable foundation for refining the tool's functionality, and their feedback fuels recommendations for its seamless integration into initial teacher training programs. | N18: 2024-03 | O18: 45783.306 | P18: 45783.306 | T18: 2 | U18: 28 | AL18: Place: Berlin, Heidelberg Publisher: Springer-Verlag | AP18: Usability evaluation; Immersive virtual reality; Classroom management; Initial teacher education; Secondary school
A19: exclude | B19: only questionnaires | C19: UCN6NLX5 | D19: conferencePaper | E19: 2022 | F19: Alvarez, Marina; Toet, Alexander; Dijkstra-Soudarissanane, Sylvie | G19: Virtual Visits: UX Evaluation of a Photorealistic AR-based Video Communication Tool | H19: Proceedings of the 1st Workshop on Interactive EXtended Reality | I19: 978-1-4503-9501-4 | K19: 10.1145/3552483.3556462 | L19: https://doi.org/10.1145/3552483.3556462 | M19: Social communication is increasingly performed through video communication (VC) tools such as Teams or Zoom. Although VC is an effective way to maintain relationships remotely, it is still limited in creating a sense of social connectedness since the interaction does not feel as natural as a physical encounter. We evaluated the user experience of a new photorealistic VC tool based on augmented reality (AR) compared with a popular VC tool (MS Teams), focusing on the feeling of social presence they provide. Participants experienced one of the systems and answered a questionnaire about their experience. In the AR condition, participants perceived a 3D image of the remote person projected in their local background (Fig.1). In the "regular video call" condition, using MS Teams, participants perceived a 2D image of the remote person in the remote background. The variables measured were social presence, interpersonal closeness, global user experience, duration of calls and perception of time, behaviour, and attitude toward the AR tool. No significant differences were found in subjective measures of social presence, interpersonal closeness, and global UX. There were also no significant differences in the duration of calls or time perception per condition. However, behavioural analysis showed that with the AR tool participants used significantly more hand gestures (non-verbal communication), showed a more relaxed attitude and laughed more frequently. Although we did not find any evidence that it provides more social presence, the AR communication tool appears to induce more natural behaviour. Both conditions received high scores on social presence and global UX. Qualitative analysis of open questions and comments showed that the human-sized image of the communication partner was the main factor driving these scores and suggested improvements for future system design. | N19: 2022 | O19: 45783.306 | P19: 45783.306 | R19: 69–75 | Y19: IXR '22 | AC19: Association for Computing Machinery | AD19: New York, NY, USA | AL19: event-place: Lisboa, Portugal | AP19: augmented reality; user experience; social connectedness; social presence; social xr; video-communication
A20: exclude | B20: only questionnaires | C20: YUQQ9FTL | D20: journalArticle | E20: 2023 | F20: Amara, K.; Kerdjidj, O.; Guerroudji, M.A.; Zenati, N.; Djekoune, O. | G20: Augmented Reality Visualization and Interaction for COVID-19 CT-Scan NN Automated Segmentation: A Validation Study | H20: IEEE Sensors Journal | J20: 1530437X (ISSN) | K20: 10.1109/JSEN.2023.3265997 | L20: https://www.scopus.com/inward/record.uri?eid=2-s2.0-85153481522&doi=10.1109%2fJSEN.2023.3265997&partnerID=40&md5=55256a5bb0b3a21152d608100598b065 | M20: Although medical imaging technology has persisted in evolving over the last decades, the techniques and technologies used for analytical and visualization purposes have remained constant. Manual or semiautomatic segmentation is, in many cases, complicated. It requires the intervention of a specialist and is time-consuming, especially during the coronavirus disease (COVID-19) pandemic, which has had devastating medical and economic consequences. Processing and visualizing medical images with advanced techniques represent medical professionals' breakthroughs. This article studies how augmented reality (AR) and artificial intelligence (AI) can transform medical practice during COVID-19 and post-COVID-19 pandemic. Here, we report an AR visualization and interaction platform; it covers the whole process from uploading chest computed tomography (CT)-scan images to automatic segmentation-based deep learning, 3-D reconstruction, 3-D visualization, and manipulation. AR provides a more realistic 3-D visualization system, allowing doctors to effectively interact with the generated 3-D model of segmented lungs and COVID-19 lesions. We use the U-Net neural network (NN) for automated segmentation. The statistical measures obtained using the Dice score, pixel accuracy, sensitivity, G -mean, and specificity are 0.749, 0.949, 0.956, 0.955, and 0.954, respectively. The user-friendliness and usability are objectified by a formal user study that compared our AR-assisted design to the standard diagnosis setup. One hundred and six doctors and medical students, including eight senior medical lecturers, volunteered to assess our platform. The platform could be used as an aid-diagnosis tool to identify and analyze the COVID-19 infectious or as a training tool for residents and medical students. The prototype can be extended to other pulmonary pathologies. © 2001-2012 IEEE. | N20: 2023 | O20: 45783.3 | P20: 45783.3 | R20: 12114-12123 | T20: 11 | U20: 23 | W20: IEEE Sensors J. | AE20: English | AH20: Scopus | AL20: Publisher: Institute of Electrical and Electronics Engineers Inc. | AP20: Diagnosis; Automation; Augmented reality; Reality visualization; 3D modeling; Three dimensional computer graphics; Visualization; deep learning; Deep learning; Computerized tomography; Image segmentation; Neural-networks; Medical imaging; AR interaction; AR visualization; augmented reality (AR); Augmented reality interaction; Augmented reality visualization; automated segmentation; Automated segmentation; coronavirus disease (COVID-19); COVID-19; CT-scan; medical imaging; Medical students; U-net; U-Net; Validation study
A21: exclude | B21: only questionnaires | C21: Z3VZPTHV | D21: journalArticle | E21: 2023 | F21: Anderies; Marvella, Maevy; Hakim, Nissa Adila; Seciawanto, Priskilla Adriani; Chowanda, Andry | G21: Implementation of Augmented Reality in Android-based Application to Promote Indonesian Tourism | H21: Procedia Comput. Sci. | J21: 1877-0509 | K21: 10.1016/j.procs.2023.10.560 | L21: https://doi.org/10.1016/j.procs.2023.10.560 | N21: 2023-01 | O21: 45783.306 | P21: 45783.306 | R21: 573–581 | T21: C | U21: 227 | AL21: Place: NLD Publisher: Elsevier Science Publishers B. V. | AP21: Augmented Reality; Usability Testing; Android; Indonesian Tourism
A22: exclude | B22: irrelevant | C22: M9V853HD | D22: conferencePaper | E22: 2020 | F22: Anderson, Sarah E. | G22: Virtual Reality for Safety and Independence in Everyday Activities | H22: 2020 IEEE Conference on Virtual Reality and 3D User Interfaces Abstracts and Workshops (VRW) | I22: 978-1-7281-6532-5 | K22: 10.1109/VRW50115.2020.00118 | L22: https://ieeexplore.ieee.org/document/9090475/ | N22: 2020-03 | O22: 45783.311 | P22: 45783.311 | Q22: 45783.311 | R22: 533-534 | AC22: IEEE | AD22: Atlanta, GA, USA | AF22: https://ieeexplore.ieee.org/Xplorehelp/downloads/license-information/IEEE.html | AJ22: DOI.org (Crossref) | BV22: 2020 IEEE Conference on Virtual Reality and 3D User Interfaces Abstracts and Workshops (VRW)
A23: exclude | B23: only questionnaires | C23: 3XMX9UPU | D23: conferencePaper | E23: 2019 | F23: Andri, C.; Alkawaz, M.H.; Waheed, S.R. | G23: Examining Effectiveness and User Experiences in 3D Mobile based Augmented Reality for MSU Virtual Tour | H23: IEEE Int. Conf. Autom. Control Intell. Syst., I2CACIS - Proc. | I23: 978-172810784-4 (ISBN) | K23: 10.1109/I2CACIS.2019.8825054 | L23: https://www.scopus.com/inward/record.uri?eid=2-s2.0-85072923510&doi=10.1109%2fI2CACIS.2019.8825054&partnerID=40&md5=4acf3b96b28372ad9681568c2f56e19a | M23: A campus tour is a time-consuming event and human resource intensive task. It is not always possible for visitors to visit all the facilities on a one-day tour due to the time limit or some activities on campus that cannot be disturbed. Along with technological advancements, some universities began to use multimedia technology as a supporting media for campus tour activities. This paper presents the mobile augmented reality and virtual tour application for Management and Science University (MSU). This application will able to help visitors in the process of obtaining such information on MSU in a very simple way by augmented reality feature, and let the visitors become familiar with MSU's environment by virtual tour feature. This project also presents the main use cases covered by the application and describes the main feature components. Furthermore, the evaluation of the application based on user testing is also explained. © 2019 IEEE. | N23: 2019 | O23: 45783.3 | P23: 45783.3 | R23: 161-167 | AC23: Institute of Electrical and Electronics Engineers Inc. | AE23: English | AH23: Scopus | AL23: Journal Abbreviation: IEEE Int. Conf. Autom. Control Intell. Syst., I2CACIS - Proc. | AP23: Mobile applications; Automation; augmented reality; Augmented reality; 3D modeling; 3D models; Three dimensional computer graphics; User experience; Technological advancement; Intelligent systems; Multimedia systems; mobile application; Mobile augmented reality; User testing; campus tour; Multimedia technologies; Process control; virtual tour; Virtual tour | BV23: 2019 IEEE International Conference on Automatic Control and Intelligent Systems, I2CACIS 2019 - Proceedings
A24: for-fulltext | B24: multimodal ux NN | C24: ID2E66RY | D24: journalArticle | E24: 2025 | F24: Pannattee, Peerawat; Shimada, Shogo; Yem, Vibol; Nishiuchi, Nobuyuki | G24: A deep learning framework for automatic assessment of presence in virtual reality using multimodal behavioral cues | H24: Neural Comput. Appl. | J24: 0941-0643 | K24: 10.1007/s00521-024-10943-3 | L24: https://doi.org/10.1007/s00521-024-10943-3 | M24: Effective development of virtual reality (VR) applications is heavily reliant on the evaluation of user experience (UX). However, traditional methods such as questionnaires have inherent limitations which hinder their ability to capture nuanced behavioral responses and impede the agility of VR content creation: They are time-consuming, burdensome for users, and require significant human effort for interpretation. This study introduces an automated framework aimed at addressing the limitations of questionnaire-based evaluations to assess UX in VR. Our primary focus is to validate the concept of this framework through assessment of the sense of presence (SOP), a crucial psychological perception with significant impact on VR UX. Our proposed framework utilizes a deep neural network (DNN) to analyze patterns in multimodal behavioral cues, including facial expressions, head movements, and hand movements, to predict scores from the Igroup Presence Questionnaire (IPQ). Additionally, we introduce two statistical profiles: the Visual Entropy Profile (VEP), which offers insights into visual complexity by depicting scene entropy, and the Experiential Presence Profile (EPP), which is designed to capture users’ historical SOP levels to enable personalized baseline and sensitivity estimation. The proposed framework achieves a significant correlation between actual and predicted IPQ scores, with a Spearman’s rank correlation coefficient of 0.7303, showcasing the potential of DNNs in analyzing complex behavioral signals and automating SOP assessment. This study represents a pioneering effort in leveraging DNNs for the automatic assessment of SOP and paves the way for future advances in automatically assessing VR UX and unlocking new opportunities in the field. | N24: 2025-01 | O24: 45783.306 | P24: 45783.376 | R24: 6283–6303 | T24: 8 | U24: 37 | AL24: Place: Berlin, Heidelberg Publisher: Springer-Verlag | AP24: Virtual environments; Virtual reality; Virtualization; Users' experiences; Deep learning; Deep neural networks; Automatic assessment; Behavioral cues; Behavioral response; Contrastive Learning; Economic and social effects; Evaluation of users; Inherent limitations; Learning frameworks; Multi-modal; Sense of presence; Sense of presences; User experience
A25: exclude | B25: only questionnaires | C25: RD76TVS3 | D25: conferencePaper | E25: 2024 | F25: Anggraini, Lisa; Santoso, Meilinda; Sunardi | G25: UX Analysis of Augmented Reality in E-Commerce Marketing Using the System Usability Scale and Usability Testing Method | H25: 2024 10th International HCI and UX Conference in Indonesia (CHIuXiD) | I25: 979-8-3503-8043-9 | K25: 10.1109/CHIuXiD64022.2024.10860502 | L25: https://ieeexplore.ieee.org/document/10860502/ | N25: 45611 | O25: 45783.311 | P25: 45783.311 | Q25: 45783.311 | R25: 72-77 | AC25: IEEE | AD25: Jakarta, Indonesia | AF25: https://doi.org/10.15223/policy-029 | AJ25: DOI.org (Crossref) | BV25: 2024 10th International HCI and UX Conference in Indonesia (CHIuXiD)
A26: for-fulltext | B26: physiological factors | C26: M9YJKLGD | D26: journalArticle | E26: 2016 | F26: Bian, Yulong; Yang, Chenglei; Gao, Fengqiang; Li, Huiyu; Zhou, Shisheng; Li, Hanchao; Sun, Xiaowen; Meng, Xiangxu | G26: A framework for physiological indicators of flow in VR games: construction and preliminary evaluation | H26: Personal Ubiquitous Comput. | J26: 1617-4909 | K26: 10.1007/s00779-016-0953-5 | L26: https://doi.org/10.1007/s00779-016-0953-5 | M26: Flow experience is often considered as an important standard of ideal user experience (UX). Till now, flow is mainly measured via self-report questionnaires, which cannot evaluate flow immediately and objectively. In this paper, we constructed a physiological evaluation model to evaluate flow in virtual reality (VR) game. The evaluation model consists of five first-level indicators and their respective second-level indicators. Then, we conducted an empirical experiment to test the effectiveness of partial indicators to predict flow experience. Most results supported the model and revealed that heart rate, interbeat interval, heart rate variability (HRV), low-frequency HRV (LF-HRV), high-frequency HRV (HF-HRV), and respiratory rate are all effective indicators in predicting flow experience. Further research should be conducted to improve the evaluation model and conclude practical implications in UX and VR game design. | N26: 2016-10 | O26: 45783.306 | P26: 45783.306 | R26: 821–832 | T26: 5 | U26: 20 | AL26: Place: Berlin, Heidelberg Publisher: Springer-Verlag | AP26: User experience; Flow experience; Physiological evaluation model; Virtual reality game
A27: exclude | B27: only questionnaires | C27: 23XJEEV4 | D27: conferencePaper | E27: 2022 | F27: Apraiz Iriarte, A.; Lasa Erle, G.; Serrano Muñoz, A.; Elguea Aguinaco, Í.; Arana Arexolaleiba, N. | G27: EVALUATION OF THE USER EXPERIENCE OF AN INDUSTRIAL ROBOTIC ENVIRONMENT IN VIRTUAL REALITY | H27: Proc. Int. Congr. Proj. Manag. Eng. | I27: 26955067 (ISSN); 978-840944521-9 (ISBN) | L27: https://www.scopus.com/inward/record.uri?eid=2-s2.0-85150344654&partnerID=40&md5=386cef55407747a7c1cc769e6e219485 | M27: Industry 4.0 is leading to a whole new level of process automation, thus redefining the role of humans, and altering existing jobs in yet unknown ways. Although the number of robots in the manufacturing industry has been steadily increasing for several decades, the current growth trend is remarkable given the number and variety of industries using robots. Operators need to have positive and fit-for-purpose experiences through trust-based, smooth, safe, and satisfying interaction to integrate robots as a natural part of their daily lives. In this sense, virtual reality is presented as an optimal technology to evaluate this interaction while ensuring safe conditions, but the impact it has on human factors still has unknowns to be solved. This research paper presents an evaluation study of the human factors resulting from collaboration with an industrial robot in a virtual environment taking into account the gender perspective. For this purpose, the behaviour of the users (n=8) has been analysed and the interaction has been evaluated by means of two questionnaires to correlate task performance and subjective perception. © 2022 by the authors. Licensee AEIPRO, Spain. This article is licensed under a Creative Commons Attribution-NonCommercial-NoDerivatives 4.0 International License (https://creativecommons.org/licenses/by-ncnd/4.0/) | N27: 2022 | O27: 45783.3 | P27: 45783.3 | R27: 1686-1698 | U27: 2022-July | X27: EVALUACIÓN DE LA EXPERIENCIA DE USO DE UN ENTORNO ROBÓTICO INDUSTRIAL EN REALIDAD VIRTUAL | AC27: Asociacion Espanola de Direccion e Ingenieria de Proyectos (AEIPRO) | AE27: Spanish | AH27: Scopus | AL27: Journal Abbreviation: Proc. Int. Congr. Proj. Manag. Eng. | AP27: Human Factors; Human-Robot Interaction (HRI); Interaction; User eXperience (UX); Virtual Reality (VR) | BV27: Proceedings from the International Congress on Project Management and Engineering
A28: exclude | B28: only questionnaires | C28: L2DXFNY6 | D28: journalArticle | E28: 2023 | F28: Ariano, R.; Manca, M.; Paternò, F.; Santoro, C. | G28: Smartphone-based augmented reality for end-user creation of home automations | H28: Behaviour and Information Technology | J28: 0144929X (ISSN) | K28: 10.1080/0144929X.2021.2017482 | L28: https://www.scopus.com/inward/record.uri?eid=2-s2.0-85122650527&doi=10.1080%2f0144929X.2021.2017482&partnerID=40&md5=f135cc2aee5c551306d803cd45074788 | M28: In the last few years, several end-user tools have been designed to help people who are not professional developers in programming their smart environments. However, such tools are often based on structured visual editors providing abstract representations of the available connected sensors and objects, which can be problematic for end users, and do not particularly encourage their participation. This work aims to make the end-user experience of creating everyday automations involving various types of connected sensors and objects more engaging by replacing extensive, static, structured and comprehensive abstract visual tools with more narrowed, relevant, context-sensitive, dynamic, augmented reality-based representations. We present a solution for this purpose that mobile users can exploit through their smartphone. End users can use the smartphone camera to frame the relevant sensor or object through the developed prototype, then get the current automations associated with it, edit their definition, create new ones as well as monitor the automations involving the whole current environment. We also report a first user test of the developed prototype deployed in a home equipped with connected sensors and objects, which yielded positive feedback. © 2022 Informa UK Limited, trading as Taylor & Francis Group. | N28: 2023 | O28: 45783.3 | P28: 45783.3 | R28: 124-140 | T28: 1 | U28: 42 | W28: Behav Inf Technol | AE28: English | AH28: Scopus | AL28: Publisher: Taylor and Francis Ltd. | AP28: Smart phones; Automation; Augmented reality; User interfaces; 'current; Smart homes; Feedback; Abstract representation; End-user development; End-User Development; End-users; everyday automation; Everyday automation; Home automation; Smart environment; smart home; Smartphones; Visual editors
A29: exclude | B29: irrelevant | C29: M5QUWAWH | D29: journalArticle | E29: 2016 | F29: Arroyo, I.; Giné, F.; Roig, C.; Granollers, T. | G29: Analyzing Google Earth application in a heterogeneous commodity cluster display wall | H29: Multimedia Tools and Applications | J29: 13807501 (ISSN) | K29: 10.1007/s11042-015-2859-z | L29: https://www.scopus.com/inward/record.uri?eid=2-s2.0-84940399006&doi=10.1007%2fs11042-015-2859-z&partnerID=40&md5=15a9c7d40f857984aa1e041675ce8d85 | M29: Nowadays, clusters of interconnected workstations have become a common solution for powering large composite displays, or “cluster display walls”, to visualize high resolution images. Our paper is focused on analyzing a specific cluster display wall developed by Google, named Liquid Galaxy, made up of heterogeneous commodity hardware with different degrees of heterogeneity, running master-slave (Google Earth) and client-server (Quake III Arena) multimedia applications. With this in mind, we define and test different scenarios, representing the behavior of many kinds of users. Our results show that the CPU, memory and network are good enough to execute the client-server application, while, depending on the user behavior, the external network constitutes the bottleneck of the system in Google Earth. So, the master-slave application has focused our attention. Likewise, in order to analyze the users’ point of view when interacting with Google Earth in the Liquid Galaxy, we define a new metric, named Visualization Rate (VR), which enables a relationship to be established between the user experience and the platform performance. In order to set the minimum acceptable value of the VR parameter according to users perception, we carried out different tests with real users. Then, this minimum threshold was compared with the VR value obtained from the automated benchmarking performed afterwards on clusters with different heterogeneity degrees. Finally, we analyzed the VR trend when the Liquid Galaxy is scaled from 3 up to 8 nodes in both the homogeneous and heterogeneous architectures to study the scalability of the system. © 2015, The Author(s). | N29: 2016 | O29: 45783.3 | P29: 45783.392 | R29: 11391-11416 | T29: 18 | U29: 75 | W29: Multimedia Tools Appl | AE29: English | AH29: Scopus | AL29: Publisher: Springer New York LLC | AP29: Behavioral research; Benchmarking; Client server; Client-server; Client-server applications; Cluster display wall; Galaxies; Google Earth; Google earths; Heterogeneous architectures; Liquid galaxy; Liquids; Master slave; Master-slave; Master-slave application; Multimedia applications
A30: exclude | B30: only questionnaires | C30: HSZMACV2 | D30: conferencePaper | E30: 2023 | F30: Asghar, Ikram; Ullah, Rahmat; Griffiths, Mark G; Warren, William; Dando, Luke; Davies, John | G30: A User-Centered System Usability Evaluation of a Virtual Reality Application Developed for Solar Farm Training | H30: Proceedings of the 2023 9th International Conference on Computer Technology Applications | I30: 978-1-4503-9957-9 | K30: 10.1145/3605423.3605456 | L30: https://doi.org/10.1145/3605423.3605456 | M30: The hazardous potential of the Photovoltaic (PV) industry demands the most rigorous and professional training. However, such training requires many resources and time and has potential health and safety risks. Incorporating emerging technologies in such training can be helpful. This paper proposes SolarPro, a virtual reality application for solar farm training that can aid solar farm trainees in getting initial training in the virtual environment. The application's usability is tested through multiple testing sessions with 30 participants. The testing participants experienced the virtual scenarios, completed the tasks and filled out the system usability questionnaires. The system usability scale analysis resulted in a grade A score of 81.75. The analysis based on the demographic characteristics also showed positive results. We can conclude that the SolarPro virtual reality application has high system usability. However, it is suggested to have more than just 30 respondents for the usability test to conclude more promising results.CCS CONCEPTS • Human-centered computing ∼Human computer interaction (HCI) ∼Interaction paradigms ∼Virtual reality | N30: 2023 | O30: 45783.306 | P30: 45783.306 | R30: 157–165 | Y30: ICCTA '23 | AC30: Association for Computing Machinery | AD30: New York, NY, USA | AL30: event-place: Vienna, Austria | AP30: Virtual reality; System usability; User testing; Solar farm
A31: exclude | B31: only questionnaires | C31: 5QU5RXJZ | D31: journalArticle | E31: 2022 | F31: Avan, Emre; Capin, Tolga K.; Gurcay, Hasmet; Celikcan, Ufuk | G31: Enhancing VR experience with RBF interpolation based dynamic tuning of stereoscopic rendering | H31: Comput. Graph. | J31: 0097-8493 | K31: 10.1016/j.cag.2021.09.016 | L31: https://doi.org/10.1016/j.cag.2021.09.016 | N31: 2022-02 | O31: 45783.306 | P31: 45783.306 | R31: 390–401 | T31: C | U31: 102 | AL31: Place: USA Publisher: Pergamon Press, Inc. | AP31: Virtual reality; Depth authoring; Depth perception; RBF interpolation; Stereoscopic rendering
A32: exclude | B32: only questionnaires | C32: TF2NUSK9 | D32: journalArticle | E32: 2020 | F32: Bacchin, D.; Pluchino, P.; Furlan, M.; Minen, M.; Minen, D.; Formaggia, F.; Bruschetta, M.; Beghi, A.; Gamberini, L. | G32: Subjective evaluation of autonomous and manual driving in advanced simulation | H32: Annual Review of CyberTherapy and Telemedicine | J32: 15548716 (ISSN) | L32: https://www.scopus.com/inward/record.uri?eid=2-s2.0-85115747548&partnerID=40&md5=33ff07913c01569c82082d0c5f35d1ba | M32: In the present study, we compare the user experience of driving a fully automated vehicle with that of driving a fully manual vehicle. We used a high-fidelity simulator displaying a highway road with four different obstacles. The user experience and usability of 26 participants was compared in the two conditions. The sense of presence in the simulation was also measured. The results showed differences between the two conditions. © 2020, Interactive Media Institute. All rights reserved. | N32: 2020 | O32: 45783.3 | P32: 45783.3 | R32: 81-85 | U32: 18 | W32: Annu. Rev. Cyber Ther. Telemedicine | AE32: English | AH32: Scopus | AL32: Publisher: Interactive Media Institute | AP32: usability; virtual reality; Virtual Reality; Article; controlled study; human; adult; female; male; simulation; priority journal; Autonomous Driving; car driving; human computer interaction; Human-computer Interactions
A33: exclude | B33: literature review | C33: NFYLUBG4 | D33: journalArticle | E33: 2012 | F33: Bai, Zhen; Blackwell, Alan F. | G33: Analytic review of usability evaluation in ISMAR | H33: Interacting with Computers | J33: 9535438 | K33: 10.1016/j.intcom.2012.07.004 | L33: https://academic.oup.com/iwc/article-lookup/doi/10.1016/j.intcom.2012.07.004 | N33: 2012-11 | O33: 45783.306 | P33: 45783.392 | Q33: 45783.311 | R33: 450-460 | T33: 6 | U33: 24 | W33: Interacting with Computers | AE33: en | AJ33: DOI.org (Crossref) | AP33: Augmented Reality; Usability evaluation; User experience; Collaboration
A34: exclude | B34: irrelevant | C34: 92J83N9M | D34: journalArticle | E34: 2010 | F34: Baillie, S.; Crossan, A.; Brewster, S.A.; May, S.A.; Mellor, D.J. | G34: Evaluating an automated haptic simulator designed for veterinary students to learn bovine rectal palpation | H34: Simulation in Healthcare | J34: 1559713X (ISSN) | K34: 10.1097/SIH.0b013e3181e369bf | L34: https://www.scopus.com/inward/record.uri?eid=2-s2.0-78049290337&doi=10.1097%2fSIH.0b013e3181e369bf&partnerID=40&md5=0a7dce1df967f77e9127ebfdfb4b7134 | M34: INTRODUCTION:: Simulators provide a potential solution to some of the challenges faced when teaching internal examinations to medical or veterinary students. A virtual reality simulator, the Haptic Cow, has been developed to teach bovine rectal palpation to veterinary students, and significant training benefits have been demonstrated. However, the training needs to be delivered by an instructor, a requirement that limits availability. This article describes the development and evaluation of an automated version that students could use on their own. METHODS:: An automated version was developed based on a recording of an expert's examination. The performance of two groups of eight students was compared. All students had undergone the traditional training in the course, namely lectures and laboratory practicals, and then group S used the simulator whereas group R had no additional training. The students were set the task of finding the uterus when examining cows. The simulator was then made available to students, and feedback about the "usability" was gathered with a questionnaire. RESULTS:: The group whose training had been supplemented with a simulator session were significantly better at finding the uterus. The questionnaire feedback was positive and indicated that students found the simulator easy to use. CONCLUSIONS:: The automated simulator equipped students with useful skills for examining cows. In addition, a simulator that does not need the presence of an instructor will increase the availability of training for students and be a more sustainable option for institutions. Copyright © 2010 Society for Simulation in Healthcare. | N34: 2010 | O34: 45783.3 | P34: 45783.3 | R34: 261-266 | T34: 5 | U34: 5 | W34: Simul. Healthc. | AE34: English | AH34: Scopus | AP34: Humans; human; Virtual reality; Teaching; article; questionnaire; Software; education; Educational Measurement; Validation; teaching; Training; animal; Animals; Questionnaires; computer simulation; Computer Simulation; methodology; computer program; animal model; cattle; Cattle; digital rectal examination; Digital Rectal Examination; educational status; Educational Status; England; Haptic; London; Models, Animal; Palpation; rectum; Rectum; school; Schools, Veterinary; Simulator; United Kingdom; Veterinary; veterinary medicine; Veterinary Medicine
